(8620, 8779)
정확도: 0.9306264501160093

[1 0 0 1 0 1 0 0 0 0 0 1 1 0 1 1 1 0 0 1]
예측값: 0.45
질문 시간 :  221 초
예측값: 챗봇( 1 )
broker creating...
Traceback (most recent call last):
  File "newbrokerInterface.py", line 88, in <module>
    broker = Broker()
  File "newbrokerInterface.py", line 62, in __init__
    main_srv.server_bind()
  File "/usr/lib64/python3.7/socketserver.py", line 466, in server_bind
    self.socket.bind(self.server_address)
OSError: [Errno 98] Address already in use
----------------------------------------
Exception happened during processing of request from ('162.142.125.57', 47816)
Traceback (most recent call last):
  File "/usr/lib64/python3.7/socketserver.py", line 650, in process_request_thread
    self.finish_request(request, client_address)
  File "/usr/lib64/python3.7/socketserver.py", line 360, in finish_request
    self.RequestHandlerClass(request, client_address, self)
  File "/usr/lib64/python3.7/socketserver.py", line 720, in __init__
    self.handle()
  File "newbrokerInterface.py", line 35, in handle
    message = self.rfile.readline().strip()
  File "/usr/lib64/python3.7/socket.py", line 589, in readinto
    return self._sock.recv_into(b)
ConnectionResetError: [Errno 104] Connection reset by peer
----------------------------------------
----------------------------------------
Exception happened during processing of request from ('162.142.125.57', 47200)
Traceback (most recent call last):
  File "/usr/lib64/python3.7/socketserver.py", line 650, in process_request_thread
    self.finish_request(request, client_address)
  File "/usr/lib64/python3.7/socketserver.py", line 360, in finish_request
    self.RequestHandlerClass(request, client_address, self)
  File "/usr/lib64/python3.7/socketserver.py", line 720, in __init__
    self.handle()
  File "newbrokerInterface.py", line 36, in handle
    message = message.decode("utf-8")
UnicodeDecodeError: 'utf-8' codec can't decode byte 0x8a in position 13: invalid start byte
----------------------------------------
----------------------------------------
Exception happened during processing of request from ('162.142.125.57', 54038)
Traceback (most recent call last):
  File "/usr/lib64/python3.7/socketserver.py", line 650, in process_request_thread
    self.finish_request(request, client_address)
  File "/usr/lib64/python3.7/socketserver.py", line 360, in finish_request
    self.RequestHandlerClass(request, client_address, self)
  File "/usr/lib64/python3.7/socketserver.py", line 720, in __init__
    self.handle()
  File "newbrokerInterface.py", line 40, in handle
    cmd, data = message.split("?/")
ValueError: not enough values to unpack (expected 2, got 1)
----------------------------------------
----------------------------------------
Exception happened during processing of request from ('162.142.125.57', 53446)
Traceback (most recent call last):
  File "/usr/lib64/python3.7/socketserver.py", line 650, in process_request_thread
    self.finish_request(request, client_address)
  File "/usr/lib64/python3.7/socketserver.py", line 360, in finish_request
    self.RequestHandlerClass(request, client_address, self)
  File "/usr/lib64/python3.7/socketserver.py", line 720, in __init__
    self.handle()
  File "newbrokerInterface.py", line 35, in handle
    message = self.rfile.readline().strip()
  File "/usr/lib64/python3.7/socket.py", line 589, in readinto
    return self._sock.recv_into(b)
ConnectionResetError: [Errno 104] Connection reset by peer
----------------------------------------
----------------------------------------
Exception happened during processing of request from ('64.62.197.182', 45308)
Traceback (most recent call last):
  File "/usr/lib64/python3.7/socketserver.py", line 650, in process_request_thread
    self.finish_request(request, client_address)
  File "/usr/lib64/python3.7/socketserver.py", line 360, in finish_request
    self.RequestHandlerClass(request, client_address, self)
  File "/usr/lib64/python3.7/socketserver.py", line 720, in __init__
    self.handle()
  File "newbrokerInterface.py", line 36, in handle
    message = message.decode("utf-8")
UnicodeDecodeError: 'utf-8' codec can't decode byte 0x9a in position 4: invalid start byte
----------------------------------------
----------------------------------------
Exception happened during processing of request from ('220.79.210.167', 7351)
----------------------------------------
Exception happened during processing of request from ('220.79.210.167', 7350)
Traceback (most recent call last):
  File "/usr/lib64/python3.7/socketserver.py", line 650, in process_request_thread
    self.finish_request(request, client_address)
  File "/usr/lib64/python3.7/socketserver.py", line 360, in finish_request
    self.RequestHandlerClass(request, client_address, self)
  File "/usr/lib64/python3.7/socketserver.py", line 720, in __init__
    self.handle()
  File "newbrokerInterface.py", line 40, in handle
    cmd, data = message.split("?/")
ValueError: not enough values to unpack (expected 2, got 1)
----------------------------------------
Traceback (most recent call last):
  File "/usr/lib64/python3.7/socketserver.py", line 650, in process_request_thread
    self.finish_request(request, client_address)
  File "/usr/lib64/python3.7/socketserver.py", line 360, in finish_request
    self.RequestHandlerClass(request, client_address, self)
  File "/usr/lib64/python3.7/socketserver.py", line 720, in __init__
    self.handle()
  File "newbrokerInterface.py", line 40, in handle
    cmd, data = message.split("?/")
ValueError: not enough values to unpack (expected 2, got 1)
----------------------------------------
----------------------------------------
Exception happened during processing of request from ('220.79.210.167', 7380)
Traceback (most recent call last):
  File "/usr/lib64/python3.7/socketserver.py", line 650, in process_request_thread
    self.finish_request(request, client_address)
  File "/usr/lib64/python3.7/socketserver.py", line 360, in finish_request
    self.RequestHandlerClass(request, client_address, self)
  File "/usr/lib64/python3.7/socketserver.py", line 720, in __init__
    self.handle()
  File "newbrokerInterface.py", line 43, in handle
    data = json.loads(data)
  File "/usr/lib64/python3.7/json/__init__.py", line 348, in loads
    return _default_decoder.decode(s)
  File "/usr/lib64/python3.7/json/decoder.py", line 337, in decode
    obj, end = self.raw_decode(s, idx=_w(s, 0).end())
  File "/usr/lib64/python3.7/json/decoder.py", line 355, in raw_decode
    raise JSONDecodeError("Expecting value", s, err.value) from None
json.decoder.JSONDecodeError: Expecting value: line 1 column 1 (char 0)
----------------------------------------
----------------------------------------
Exception happened during processing of request from ('220.79.210.167', 7383)
Traceback (most recent call last):
  File "/usr/lib64/python3.7/socketserver.py", line 650, in process_request_thread
    self.finish_request(request, client_address)
  File "/usr/lib64/python3.7/socketserver.py", line 360, in finish_request
    self.RequestHandlerClass(request, client_address, self)
  File "/usr/lib64/python3.7/socketserver.py", line 720, in __init__
    self.handle()
  File "newbrokerInterface.py", line 43, in handle
    data = json.loads(data)
  File "/usr/lib64/python3.7/json/__init__.py", line 348, in loads
    return _default_decoder.decode(s)
  File "/usr/lib64/python3.7/json/decoder.py", line 337, in decode
    obj, end = self.raw_decode(s, idx=_w(s, 0).end())
  File "/usr/lib64/python3.7/json/decoder.py", line 355, in raw_decode
    raise JSONDecodeError("Expecting value", s, err.value) from None
json.decoder.JSONDecodeError: Expecting value: line 1 column 1 (char 0)
----------------------------------------
----------------------------------------
Exception happened during processing of request from ('220.79.210.167', 7392)
Traceback (most recent call last):
  File "/usr/lib64/python3.7/socketserver.py", line 650, in process_request_thread
    self.finish_request(request, client_address)
  File "/usr/lib64/python3.7/socketserver.py", line 360, in finish_request
    self.RequestHandlerClass(request, client_address, self)
  File "/usr/lib64/python3.7/socketserver.py", line 720, in __init__
    self.handle()
  File "newbrokerInterface.py", line 43, in handle
    data = json.loads(data)
  File "/usr/lib64/python3.7/json/__init__.py", line 348, in loads
    return _default_decoder.decode(s)
  File "/usr/lib64/python3.7/json/decoder.py", line 337, in decode
    obj, end = self.raw_decode(s, idx=_w(s, 0).end())
  File "/usr/lib64/python3.7/json/decoder.py", line 353, in raw_decode
    obj, end = self.scan_once(s, idx)
json.decoder.JSONDecodeError: Expecting property name enclosed in double quotes: line 1 column 2 (char 1)
----------------------------------------
----------------------------------------
Exception happened during processing of request from ('71.6.158.166', 54230)
Traceback (most recent call last):
  File "/usr/lib64/python3.7/socketserver.py", line 650, in process_request_thread
    self.finish_request(request, client_address)
  File "/usr/lib64/python3.7/socketserver.py", line 360, in finish_request
    self.RequestHandlerClass(request, client_address, self)
  File "/usr/lib64/python3.7/socketserver.py", line 720, in __init__
    self.handle()
  File "newbrokerInterface.py", line 36, in handle
    message = message.decode("utf-8")
UnicodeDecodeError: 'utf-8' codec can't decode byte 0xfc in position 8: invalid start byte
----------------------------------------
----------------------------------------
Exception happened during processing of request from ('71.6.158.166', 55002)
Traceback (most recent call last):
  File "/usr/lib64/python3.7/socketserver.py", line 650, in process_request_thread
    self.finish_request(request, client_address)
  File "/usr/lib64/python3.7/socketserver.py", line 360, in finish_request
    self.RequestHandlerClass(request, client_address, self)
  File "/usr/lib64/python3.7/socketserver.py", line 720, in __init__
    self.handle()
  File "newbrokerInterface.py", line 36, in handle
    message = message.decode("utf-8")
UnicodeDecodeError: 'utf-8' codec can't decode byte 0x80 in position 0: invalid start byte
----------------------------------------
----------------------------------------
Exception happened during processing of request from ('71.6.158.166', 55140)
Traceback (most recent call last):
  File "/usr/lib64/python3.7/socketserver.py", line 650, in process_request_thread
    self.finish_request(request, client_address)
  File "/usr/lib64/python3.7/socketserver.py", line 360, in finish_request
    self.RequestHandlerClass(request, client_address, self)
  File "/usr/lib64/python3.7/socketserver.py", line 720, in __init__
    self.handle()
  File "newbrokerInterface.py", line 36, in handle
    message = message.decode("utf-8")
UnicodeDecodeError: 'utf-8' codec can't decode byte 0x80 in position 0: invalid start byte
----------------------------------------
----------------------------------------
Exception happened during processing of request from ('71.6.158.166', 56634)
Traceback (most recent call last):
  File "/usr/lib64/python3.7/socketserver.py", line 650, in process_request_thread
    self.finish_request(request, client_address)
  File "/usr/lib64/python3.7/socketserver.py", line 360, in finish_request
    self.RequestHandlerClass(request, client_address, self)
  File "/usr/lib64/python3.7/socketserver.py", line 720, in __init__
    self.handle()
  File "newbrokerInterface.py", line 40, in handle
    cmd, data = message.split("?/")
ValueError: not enough values to unpack (expected 2, got 1)
----------------------------------------
----------------------------------------
Exception happened during processing of request from ('35.195.93.98', 40022)
Traceback (most recent call last):
  File "/usr/lib64/python3.7/socketserver.py", line 650, in process_request_thread
    self.finish_request(request, client_address)
  File "/usr/lib64/python3.7/socketserver.py", line 360, in finish_request
    self.RequestHandlerClass(request, client_address, self)
  File "/usr/lib64/python3.7/socketserver.py", line 720, in __init__
    self.handle()
  File "newbrokerInterface.py", line 36, in handle
    message = message.decode("utf-8")
UnicodeDecodeError: 'utf-8' codec can't decode byte 0xd7 in position 4: invalid continuation byte
----------------------------------------
----------------------------------------
Exception happened during processing of request from ('45.155.205.233', 38550)
Traceback (most recent call last):
  File "/usr/lib64/python3.7/socketserver.py", line 650, in process_request_thread
    self.finish_request(request, client_address)
  File "/usr/lib64/python3.7/socketserver.py", line 360, in finish_request
    self.RequestHandlerClass(request, client_address, self)
  File "/usr/lib64/python3.7/socketserver.py", line 720, in __init__
    self.handle()
  File "newbrokerInterface.py", line 36, in handle
    message = message.decode("utf-8")
UnicodeDecodeError: 'utf-8' codec can't decode byte 0xc2 in position 21: invalid continuation byte
----------------------------------------
----------------------------------------
Exception happened during processing of request from ('45.155.205.233', 58196)
Traceback (most recent call last):
  File "/usr/lib64/python3.7/socketserver.py", line 650, in process_request_thread
    self.finish_request(request, client_address)
  File "/usr/lib64/python3.7/socketserver.py", line 360, in finish_request
    self.RequestHandlerClass(request, client_address, self)
  File "/usr/lib64/python3.7/socketserver.py", line 720, in __init__
    self.handle()
  File "newbrokerInterface.py", line 36, in handle
    message = message.decode("utf-8")
UnicodeDecodeError: 'utf-8' codec can't decode byte 0xcc in position 21: invalid continuation byte
----------------------------------------
----------------------------------------
Exception happened during processing of request from ('45.155.205.233', 49266)
Traceback (most recent call last):
  File "/usr/lib64/python3.7/socketserver.py", line 650, in process_request_thread
    self.finish_request(request, client_address)
  File "/usr/lib64/python3.7/socketserver.py", line 360, in finish_request
    self.RequestHandlerClass(request, client_address, self)
  File "/usr/lib64/python3.7/socketserver.py", line 720, in __init__
    self.handle()
  File "newbrokerInterface.py", line 36, in handle
    message = message.decode("utf-8")
UnicodeDecodeError: 'utf-8' codec can't decode byte 0xd4 in position 21: invalid continuation byte
----------------------------------------
----------------------------------------
Exception happened during processing of request from ('45.155.205.233', 40702)
Traceback (most recent call last):
  File "/usr/lib64/python3.7/socketserver.py", line 650, in process_request_thread
    self.finish_request(request, client_address)
  File "/usr/lib64/python3.7/socketserver.py", line 360, in finish_request
    self.RequestHandlerClass(request, client_address, self)
  File "/usr/lib64/python3.7/socketserver.py", line 720, in __init__
    self.handle()
  File "newbrokerInterface.py", line 36, in handle
    message = message.decode("utf-8")
UnicodeDecodeError: 'utf-8' codec can't decode byte 0xe4 in position 21: invalid continuation byte
----------------------------------------
----------------------------------------
Exception happened during processing of request from ('45.155.205.233', 60690)
Traceback (most recent call last):
  File "/usr/lib64/python3.7/socketserver.py", line 650, in process_request_thread
    self.finish_request(request, client_address)
  File "/usr/lib64/python3.7/socketserver.py", line 360, in finish_request
    self.RequestHandlerClass(request, client_address, self)
  File "/usr/lib64/python3.7/socketserver.py", line 720, in __init__
    self.handle()
  File "newbrokerInterface.py", line 36, in handle
    message = message.decode("utf-8")
UnicodeDecodeError: 'utf-8' codec can't decode byte 0xd8 in position 21: invalid continuation byte
----------------------------------------
----------------------------------------
Exception happened during processing of request from ('45.155.205.233', 52102)
Traceback (most recent call last):
  File "/usr/lib64/python3.7/socketserver.py", line 650, in process_request_thread
    self.finish_request(request, client_address)
  File "/usr/lib64/python3.7/socketserver.py", line 360, in finish_request
    self.RequestHandlerClass(request, client_address, self)
  File "/usr/lib64/python3.7/socketserver.py", line 720, in __init__
    self.handle()
  File "newbrokerInterface.py", line 36, in handle
    message = message.decode("utf-8")
UnicodeDecodeError: 'utf-8' codec can't decode byte 0xcc in position 21: invalid continuation byte
----------------------------------------
----------------------------------------
Exception happened during processing of request from ('45.155.205.233', 58016)
Traceback (most recent call last):
  File "/usr/lib64/python3.7/socketserver.py", line 650, in process_request_thread
    self.finish_request(request, client_address)
  File "/usr/lib64/python3.7/socketserver.py", line 360, in finish_request
    self.RequestHandlerClass(request, client_address, self)
  File "/usr/lib64/python3.7/socketserver.py", line 720, in __init__
    self.handle()
  File "newbrokerInterface.py", line 36, in handle
    message = message.decode("utf-8")
UnicodeDecodeError: 'utf-8' codec can't decode byte 0xba in position 21: invalid start byte
----------------------------------------
----------------------------------------
Exception happened during processing of request from ('45.155.205.233', 47346)
Traceback (most recent call last):
  File "/usr/lib64/python3.7/socketserver.py", line 650, in process_request_thread
    self.finish_request(request, client_address)
  File "/usr/lib64/python3.7/socketserver.py", line 360, in finish_request
    self.RequestHandlerClass(request, client_address, self)
  File "/usr/lib64/python3.7/socketserver.py", line 720, in __init__
    self.handle()
  File "newbrokerInterface.py", line 36, in handle
    message = message.decode("utf-8")
UnicodeDecodeError: 'utf-8' codec can't decode byte 0xc8 in position 21: invalid continuation byte
----------------------------------------
----------------------------------------
Exception happened during processing of request from ('45.155.205.233', 38310)
Traceback (most recent call last):
  File "/usr/lib64/python3.7/socketserver.py", line 650, in process_request_thread
    self.finish_request(request, client_address)
  File "/usr/lib64/python3.7/socketserver.py", line 360, in finish_request
    self.RequestHandlerClass(request, client_address, self)
  File "/usr/lib64/python3.7/socketserver.py", line 720, in __init__
    self.handle()
  File "newbrokerInterface.py", line 36, in handle
    message = message.decode("utf-8")
UnicodeDecodeError: 'utf-8' codec can't decode byte 0xce in position 21: invalid continuation byte
----------------------------------------
----------------------------------------
Exception happened during processing of request from ('192.241.214.20', 44714)
Traceback (most recent call last):
  File "/usr/lib64/python3.7/socketserver.py", line 650, in process_request_thread
    self.finish_request(request, client_address)
  File "/usr/lib64/python3.7/socketserver.py", line 360, in finish_request
    self.RequestHandlerClass(request, client_address, self)
  File "/usr/lib64/python3.7/socketserver.py", line 720, in __init__
    self.handle()
  File "newbrokerInterface.py", line 40, in handle
    cmd, data = message.split("?/")
ValueError: not enough values to unpack (expected 2, got 1)
----------------------------------------
----------------------------------------
Exception happened during processing of request from ('192.241.215.57', 55076)
Traceback (most recent call last):
  File "/usr/lib64/python3.7/socketserver.py", line 650, in process_request_thread
    self.finish_request(request, client_address)
  File "/usr/lib64/python3.7/socketserver.py", line 360, in finish_request
    self.RequestHandlerClass(request, client_address, self)
  File "/usr/lib64/python3.7/socketserver.py", line 720, in __init__
    self.handle()
  File "newbrokerInterface.py", line 40, in handle
    cmd, data = message.split("?/")
ValueError: not enough values to unpack (expected 2, got 1)
----------------------------------------
----------------------------------------
Exception happened during processing of request from ('167.94.138.59', 40812)
Traceback (most recent call last):
  File "/usr/lib64/python3.7/socketserver.py", line 650, in process_request_thread
    self.finish_request(request, client_address)
  File "/usr/lib64/python3.7/socketserver.py", line 360, in finish_request
    self.RequestHandlerClass(request, client_address, self)
  File "/usr/lib64/python3.7/socketserver.py", line 720, in __init__
    self.handle()
  File "newbrokerInterface.py", line 35, in handle
    message = self.rfile.readline().strip()
  File "/usr/lib64/python3.7/socket.py", line 589, in readinto
    return self._sock.recv_into(b)
ConnectionResetError: [Errno 104] Connection reset by peer
----------------------------------------
----------------------------------------
Exception happened during processing of request from ('167.94.138.59', 41730)
Traceback (most recent call last):
  File "/usr/lib64/python3.7/socketserver.py", line 650, in process_request_thread
    self.finish_request(request, client_address)
  File "/usr/lib64/python3.7/socketserver.py", line 360, in finish_request
    self.RequestHandlerClass(request, client_address, self)
  File "/usr/lib64/python3.7/socketserver.py", line 720, in __init__
    self.handle()
  File "newbrokerInterface.py", line 36, in handle
    message = message.decode("utf-8")
UnicodeDecodeError: 'utf-8' codec can't decode byte 0x86 in position 11: invalid start byte
----------------------------------------
----------------------------------------
Exception happened during processing of request from ('167.94.138.59', 50376)
Traceback (most recent call last):
  File "/usr/lib64/python3.7/socketserver.py", line 650, in process_request_thread
    self.finish_request(request, client_address)
  File "/usr/lib64/python3.7/socketserver.py", line 360, in finish_request
    self.RequestHandlerClass(request, client_address, self)
  File "/usr/lib64/python3.7/socketserver.py", line 720, in __init__
    self.handle()
  File "newbrokerInterface.py", line 40, in handle
    cmd, data = message.split("?/")
ValueError: not enough values to unpack (expected 2, got 1)
----------------------------------------
----------------------------------------
Exception happened during processing of request from ('167.94.138.59', 55024)
Traceback (most recent call last):
  File "/usr/lib64/python3.7/socketserver.py", line 650, in process_request_thread
    self.finish_request(request, client_address)
  File "/usr/lib64/python3.7/socketserver.py", line 360, in finish_request
    self.RequestHandlerClass(request, client_address, self)
  File "/usr/lib64/python3.7/socketserver.py", line 720, in __init__
    self.handle()
  File "newbrokerInterface.py", line 35, in handle
    message = self.rfile.readline().strip()
  File "/usr/lib64/python3.7/socket.py", line 589, in readinto
    return self._sock.recv_into(b)
ConnectionResetError: [Errno 104] Connection reset by peer
----------------------------------------
----------------------------------------
Exception happened during processing of request from ('209.17.97.58', 59051)
Traceback (most recent call last):
  File "/usr/lib64/python3.7/socketserver.py", line 650, in process_request_thread
    self.finish_request(request, client_address)
  File "/usr/lib64/python3.7/socketserver.py", line 360, in finish_request
    self.RequestHandlerClass(request, client_address, self)
  File "/usr/lib64/python3.7/socketserver.py", line 720, in __init__
    self.handle()
  File "newbrokerInterface.py", line 40, in handle
    cmd, data = message.split("?/")
ValueError: not enough values to unpack (expected 2, got 1)
----------------------------------------
----------------------------------------
Exception happened during processing of request from ('103.203.57.26', 53508)
Traceback (most recent call last):
  File "/usr/lib64/python3.7/socketserver.py", line 650, in process_request_thread
    self.finish_request(request, client_address)
  File "/usr/lib64/python3.7/socketserver.py", line 360, in finish_request
    self.RequestHandlerClass(request, client_address, self)
  File "/usr/lib64/python3.7/socketserver.py", line 720, in __init__
    self.handle()
  File "newbrokerInterface.py", line 40, in handle
    cmd, data = message.split("?/")
ValueError: not enough values to unpack (expected 2, got 1)
----------------------------------------
----------------------------------------
Exception happened during processing of request from ('103.203.57.26', 53558)
Traceback (most recent call last):
  File "/usr/lib64/python3.7/socketserver.py", line 650, in process_request_thread
    self.finish_request(request, client_address)
  File "/usr/lib64/python3.7/socketserver.py", line 360, in finish_request
    self.RequestHandlerClass(request, client_address, self)
  File "/usr/lib64/python3.7/socketserver.py", line 720, in __init__
    self.handle()
  File "newbrokerInterface.py", line 40, in handle
    cmd, data = message.split("?/")
ValueError: not enough values to unpack (expected 2, got 1)
----------------------------------------
----------------------------------------
Exception happened during processing of request from ('162.142.125.57', 34104)
Traceback (most recent call last):
  File "/usr/lib64/python3.7/socketserver.py", line 650, in process_request_thread
    self.finish_request(request, client_address)
  File "/usr/lib64/python3.7/socketserver.py", line 360, in finish_request
    self.RequestHandlerClass(request, client_address, self)
  File "/usr/lib64/python3.7/socketserver.py", line 720, in __init__
    self.handle()
  File "newbrokerInterface.py", line 35, in handle
    message = self.rfile.readline().strip()
  File "/usr/lib64/python3.7/socket.py", line 589, in readinto
    return self._sock.recv_into(b)
ConnectionResetError: [Errno 104] Connection reset by peer
----------------------------------------
----------------------------------------
Exception happened during processing of request from ('162.142.125.57', 59148)
Traceback (most recent call last):
  File "/usr/lib64/python3.7/socketserver.py", line 650, in process_request_thread
    self.finish_request(request, client_address)
  File "/usr/lib64/python3.7/socketserver.py", line 360, in finish_request
    self.RequestHandlerClass(request, client_address, self)
  File "/usr/lib64/python3.7/socketserver.py", line 720, in __init__
    self.handle()
  File "newbrokerInterface.py", line 36, in handle
    message = message.decode("utf-8")
UnicodeDecodeError: 'utf-8' codec can't decode byte 0xb4 in position 11: invalid start byte
----------------------------------------
----------------------------------------
Exception happened during processing of request from ('162.142.125.57', 37760)
Traceback (most recent call last):
  File "/usr/lib64/python3.7/socketserver.py", line 650, in process_request_thread
    self.finish_request(request, client_address)
  File "/usr/lib64/python3.7/socketserver.py", line 360, in finish_request
    self.RequestHandlerClass(request, client_address, self)
  File "/usr/lib64/python3.7/socketserver.py", line 720, in __init__
    self.handle()
  File "newbrokerInterface.py", line 40, in handle
    cmd, data = message.split("?/")
ValueError: not enough values to unpack (expected 2, got 1)
----------------------------------------
----------------------------------------
Exception happened during processing of request from ('162.142.125.57', 38394)
Traceback (most recent call last):
  File "/usr/lib64/python3.7/socketserver.py", line 650, in process_request_thread
    self.finish_request(request, client_address)
  File "/usr/lib64/python3.7/socketserver.py", line 360, in finish_request
    self.RequestHandlerClass(request, client_address, self)
  File "/usr/lib64/python3.7/socketserver.py", line 720, in __init__
    self.handle()
  File "newbrokerInterface.py", line 35, in handle
    message = self.rfile.readline().strip()
  File "/usr/lib64/python3.7/socket.py", line 589, in readinto
    return self._sock.recv_into(b)
ConnectionResetError: [Errno 104] Connection reset by peer
----------------------------------------
----------------------------------------
Exception happened during processing of request from ('104.152.52.165', 44257)
Traceback (most recent call last):
  File "/usr/lib64/python3.7/socketserver.py", line 650, in process_request_thread
    self.finish_request(request, client_address)
  File "/usr/lib64/python3.7/socketserver.py", line 360, in finish_request
    self.RequestHandlerClass(request, client_address, self)
  File "/usr/lib64/python3.7/socketserver.py", line 720, in __init__
    self.handle()
  File "newbrokerInterface.py", line 35, in handle
    message = self.rfile.readline().strip()
  File "/usr/lib64/python3.7/socket.py", line 589, in readinto
    return self._sock.recv_into(b)
ConnectionResetError: [Errno 104] Connection reset by peer
----------------------------------------
----------------------------------------
Exception happened during processing of request from ('54.180.161.181', 45548)
Traceback (most recent call last):
  File "/usr/lib64/python3.7/socketserver.py", line 650, in process_request_thread
    self.finish_request(request, client_address)
  File "/usr/lib64/python3.7/socketserver.py", line 360, in finish_request
    self.RequestHandlerClass(request, client_address, self)
  File "/usr/lib64/python3.7/socketserver.py", line 720, in __init__
    self.handle()
  File "newbrokerInterface.py", line 43, in handle
    data = json.loads(data)
  File "/usr/lib64/python3.7/json/__init__.py", line 348, in loads
    return _default_decoder.decode(s)
  File "/usr/lib64/python3.7/json/decoder.py", line 337, in decode
    obj, end = self.raw_decode(s, idx=_w(s, 0).end())
  File "/usr/lib64/python3.7/json/decoder.py", line 355, in raw_decode
    raise JSONDecodeError("Expecting value", s, err.value) from None
json.decoder.JSONDecodeError: Expecting value: line 1 column 1 (char 0)
----------------------------------------
----------------------------------------
Exception happened during processing of request from ('54.180.161.181', 45550)
Traceback (most recent call last):
  File "/usr/lib64/python3.7/socketserver.py", line 650, in process_request_thread
    self.finish_request(request, client_address)
  File "/usr/lib64/python3.7/socketserver.py", line 360, in finish_request
    self.RequestHandlerClass(request, client_address, self)
  File "/usr/lib64/python3.7/socketserver.py", line 720, in __init__
    self.handle()
  File "newbrokerInterface.py", line 43, in handle
    data = json.loads(data)
  File "/usr/lib64/python3.7/json/__init__.py", line 348, in loads
    return _default_decoder.decode(s)
  File "/usr/lib64/python3.7/json/decoder.py", line 337, in decode
    obj, end = self.raw_decode(s, idx=_w(s, 0).end())
  File "/usr/lib64/python3.7/json/decoder.py", line 355, in raw_decode
    raise JSONDecodeError("Expecting value", s, err.value) from None
json.decoder.JSONDecodeError: Expecting value: line 1 column 1 (char 0)
----------------------------------------
----------------------------------------
Exception happened during processing of request from ('54.180.161.181', 45552)
Traceback (most recent call last):
  File "/usr/lib64/python3.7/socketserver.py", line 650, in process_request_thread
    self.finish_request(request, client_address)
  File "/usr/lib64/python3.7/socketserver.py", line 360, in finish_request
    self.RequestHandlerClass(request, client_address, self)
  File "/usr/lib64/python3.7/socketserver.py", line 720, in __init__
    self.handle()
  File "newbrokerInterface.py", line 43, in handle
    data = json.loads(data)
  File "/usr/lib64/python3.7/json/__init__.py", line 348, in loads
    return _default_decoder.decode(s)
  File "/usr/lib64/python3.7/json/decoder.py", line 337, in decode
    obj, end = self.raw_decode(s, idx=_w(s, 0).end())
  File "/usr/lib64/python3.7/json/decoder.py", line 355, in raw_decode
    raise JSONDecodeError("Expecting value", s, err.value) from None
json.decoder.JSONDecodeError: Expecting value: line 1 column 1 (char 0)
----------------------------------------
----------------------------------------
Exception happened during processing of request from ('54.180.161.181', 45554)
Traceback (most recent call last):
  File "/usr/lib64/python3.7/socketserver.py", line 650, in process_request_thread
    self.finish_request(request, client_address)
  File "/usr/lib64/python3.7/socketserver.py", line 360, in finish_request
    self.RequestHandlerClass(request, client_address, self)
  File "/usr/lib64/python3.7/socketserver.py", line 720, in __init__
    self.handle()
  File "newbrokerInterface.py", line 43, in handle
    data = json.loads(data)
  File "/usr/lib64/python3.7/json/__init__.py", line 348, in loads
    return _default_decoder.decode(s)
  File "/usr/lib64/python3.7/json/decoder.py", line 337, in decode
    obj, end = self.raw_decode(s, idx=_w(s, 0).end())
  File "/usr/lib64/python3.7/json/decoder.py", line 355, in raw_decode
    raise JSONDecodeError("Expecting value", s, err.value) from None
json.decoder.JSONDecodeError: Expecting value: line 1 column 1 (char 0)
----------------------------------------
----------------------------------------
Exception happened during processing of request from ('54.180.161.181', 45556)
Traceback (most recent call last):
  File "/usr/lib64/python3.7/socketserver.py", line 650, in process_request_thread
    self.finish_request(request, client_address)
  File "/usr/lib64/python3.7/socketserver.py", line 360, in finish_request
    self.RequestHandlerClass(request, client_address, self)
  File "/usr/lib64/python3.7/socketserver.py", line 720, in __init__
    self.handle()
  File "newbrokerInterface.py", line 43, in handle
    data = json.loads(data)
  File "/usr/lib64/python3.7/json/__init__.py", line 348, in loads
    return _default_decoder.decode(s)
  File "/usr/lib64/python3.7/json/decoder.py", line 337, in decode
    obj, end = self.raw_decode(s, idx=_w(s, 0).end())
  File "/usr/lib64/python3.7/json/decoder.py", line 355, in raw_decode
    raise JSONDecodeError("Expecting value", s, err.value) from None
json.decoder.JSONDecodeError: Expecting value: line 1 column 1 (char 0)
----------------------------------------
----------------------------------------
Exception happened during processing of request from ('54.180.161.181', 45558)
Traceback (most recent call last):
  File "/usr/lib64/python3.7/socketserver.py", line 650, in process_request_thread
    self.finish_request(request, client_address)
  File "/usr/lib64/python3.7/socketserver.py", line 360, in finish_request
    self.RequestHandlerClass(request, client_address, self)
  File "/usr/lib64/python3.7/socketserver.py", line 720, in __init__
    self.handle()
  File "newbrokerInterface.py", line 43, in handle
    data = json.loads(data)
  File "/usr/lib64/python3.7/json/__init__.py", line 348, in loads
    return _default_decoder.decode(s)
  File "/usr/lib64/python3.7/json/decoder.py", line 337, in decode
    obj, end = self.raw_decode(s, idx=_w(s, 0).end())
  File "/usr/lib64/python3.7/json/decoder.py", line 355, in raw_decode
    raise JSONDecodeError("Expecting value", s, err.value) from None
json.decoder.JSONDecodeError: Expecting value: line 1 column 1 (char 0)
----------------------------------------
----------------------------------------
Exception happened during processing of request from ('54.180.161.181', 45560)
Traceback (most recent call last):
  File "/usr/lib64/python3.7/socketserver.py", line 650, in process_request_thread
    self.finish_request(request, client_address)
  File "/usr/lib64/python3.7/socketserver.py", line 360, in finish_request
    self.RequestHandlerClass(request, client_address, self)
  File "/usr/lib64/python3.7/socketserver.py", line 720, in __init__
    self.handle()
  File "newbrokerInterface.py", line 43, in handle
    data = json.loads(data)
  File "/usr/lib64/python3.7/json/__init__.py", line 348, in loads
    return _default_decoder.decode(s)
  File "/usr/lib64/python3.7/json/decoder.py", line 337, in decode
    obj, end = self.raw_decode(s, idx=_w(s, 0).end())
  File "/usr/lib64/python3.7/json/decoder.py", line 355, in raw_decode
    raise JSONDecodeError("Expecting value", s, err.value) from None
json.decoder.JSONDecodeError: Expecting value: line 1 column 1 (char 0)
----------------------------------------
----------------------------------------
Exception happened during processing of request from ('54.180.161.181', 45574)
Traceback (most recent call last):
  File "/usr/lib64/python3.7/socketserver.py", line 650, in process_request_thread
    self.finish_request(request, client_address)
  File "/usr/lib64/python3.7/socketserver.py", line 360, in finish_request
    self.RequestHandlerClass(request, client_address, self)
  File "/usr/lib64/python3.7/socketserver.py", line 720, in __init__
    self.handle()
  File "newbrokerInterface.py", line 43, in handle
    data = json.loads(data)
  File "/usr/lib64/python3.7/json/__init__.py", line 348, in loads
    return _default_decoder.decode(s)
  File "/usr/lib64/python3.7/json/decoder.py", line 337, in decode
    obj, end = self.raw_decode(s, idx=_w(s, 0).end())
  File "/usr/lib64/python3.7/json/decoder.py", line 355, in raw_decode
    raise JSONDecodeError("Expecting value", s, err.value) from None
json.decoder.JSONDecodeError: Expecting value: line 1 column 1 (char 0)
----------------------------------------
----------------------------------------
Exception happened during processing of request from ('54.180.161.181', 45576)
Traceback (most recent call last):
  File "/usr/lib64/python3.7/socketserver.py", line 650, in process_request_thread
    self.finish_request(request, client_address)
  File "/usr/lib64/python3.7/socketserver.py", line 360, in finish_request
    self.RequestHandlerClass(request, client_address, self)
  File "/usr/lib64/python3.7/socketserver.py", line 720, in __init__
    self.handle()
  File "newbrokerInterface.py", line 43, in handle
    data = json.loads(data)
  File "/usr/lib64/python3.7/json/__init__.py", line 348, in loads
    return _default_decoder.decode(s)
  File "/usr/lib64/python3.7/json/decoder.py", line 337, in decode
    obj, end = self.raw_decode(s, idx=_w(s, 0).end())
  File "/usr/lib64/python3.7/json/decoder.py", line 355, in raw_decode
    raise JSONDecodeError("Expecting value", s, err.value) from None
json.decoder.JSONDecodeError: Expecting value: line 1 column 1 (char 0)
----------------------------------------
----------------------------------------
Exception happened during processing of request from ('54.180.161.181', 45578)
Traceback (most recent call last):
  File "/usr/lib64/python3.7/socketserver.py", line 650, in process_request_thread
    self.finish_request(request, client_address)
  File "/usr/lib64/python3.7/socketserver.py", line 360, in finish_request
    self.RequestHandlerClass(request, client_address, self)
  File "/usr/lib64/python3.7/socketserver.py", line 720, in __init__
    self.handle()
  File "newbrokerInterface.py", line 43, in handle
    data = json.loads(data)
  File "/usr/lib64/python3.7/json/__init__.py", line 348, in loads
    return _default_decoder.decode(s)
  File "/usr/lib64/python3.7/json/decoder.py", line 337, in decode
    obj, end = self.raw_decode(s, idx=_w(s, 0).end())
  File "/usr/lib64/python3.7/json/decoder.py", line 355, in raw_decode
    raise JSONDecodeError("Expecting value", s, err.value) from None
json.decoder.JSONDecodeError: Expecting value: line 1 column 1 (char 0)
----------------------------------------
----------------------------------------
Exception happened during processing of request from ('54.180.161.181', 45594)
Traceback (most recent call last):
  File "/usr/lib64/python3.7/socketserver.py", line 650, in process_request_thread
    self.finish_request(request, client_address)
  File "/usr/lib64/python3.7/socketserver.py", line 360, in finish_request
    self.RequestHandlerClass(request, client_address, self)
  File "/usr/lib64/python3.7/socketserver.py", line 720, in __init__
    self.handle()
  File "newbrokerInterface.py", line 43, in handle
    data = json.loads(data)
  File "/usr/lib64/python3.7/json/__init__.py", line 348, in loads
    return _default_decoder.decode(s)
  File "/usr/lib64/python3.7/json/decoder.py", line 337, in decode
    obj, end = self.raw_decode(s, idx=_w(s, 0).end())
  File "/usr/lib64/python3.7/json/decoder.py", line 355, in raw_decode
    raise JSONDecodeError("Expecting value", s, err.value) from None
json.decoder.JSONDecodeError: Expecting value: line 1 column 1 (char 0)
----------------------------------------
----------------------------------------
Exception happened during processing of request from ('54.180.161.181', 45596)
Traceback (most recent call last):
  File "/usr/lib64/python3.7/socketserver.py", line 650, in process_request_thread
    self.finish_request(request, client_address)
  File "/usr/lib64/python3.7/socketserver.py", line 360, in finish_request
    self.RequestHandlerClass(request, client_address, self)
  File "/usr/lib64/python3.7/socketserver.py", line 720, in __init__
    self.handle()
